************* Module ../pyanaconda/anaconda.py
/usr/lib/python3.5/site-packages/astroid/bases.py:302: PyGIWarning: BlockDev was imported without specifying a version first. Use gi.require_version('BlockDev', '1.0') before import to ensure that the right version gets loaded.
  for res in _func(node, context, **kwargs):
Exception ignored in: <bound method Broker.__del__ of <enchant.Broker object at 0x7faf3097f7f0>>
Traceback (most recent call last):
  File "/usr/lib/python3.5/site-packages/enchant/__init__.py", line 244, in __del__
  File "/usr/lib/python3.5/site-packages/enchant/__init__.py", line 273, in _free
TypeError: 'NoneType' object is not callable
************* Module ../anaconda
/usr/lib/python3.5/site-packages/astroid/bases.py:302: PyGIWarning: BlockDev was imported without specifying a version first. Use gi.require_version('BlockDev', '1.0') before import to ensure that the right version gets loaded.
  for res in _func(node, context, **kwargs):
************* Module ../pyanaconda/ui/gui/helpers.py
Exception ignored in: <bound method Broker.__del__ of <enchant.Broker object at 0x7fd4270b47f0>>
Traceback (most recent call last):
  File "/usr/lib/python3.5/site-packages/enchant/__init__.py", line 244, in __del__
  File "/usr/lib/python3.5/site-packages/enchant/__init__.py", line 273, in _free
TypeError: 'NoneType' object is not callable
************* Module ../pyanaconda/ui/gui/spokes/software.py
Exception ignored in: <bound method Broker.__del__ of <enchant.Broker object at 0x7fad55e957f0>>
Traceback (most recent call last):
  File "/usr/lib/python3.5/site-packages/enchant/__init__.py", line 244, in __del__
  File "/usr/lib/python3.5/site-packages/enchant/__init__.py", line 273, in _free
TypeError: 'NoneType' object is not callable
************* Module ../pyanaconda/ui/gui/spokes/welcome.py
Exception ignored in: <bound method Broker.__del__ of <enchant.Broker object at 0x7feba4b907f0>>
Traceback (most recent call last):
  File "/usr/lib/python3.5/site-packages/enchant/__init__.py", line 244, in __del__
  File "/usr/lib/python3.5/site-packages/enchant/__init__.py", line 273, in _free
TypeError: 'NoneType' object is not callable
************* Module ../pyanaconda/ui/gui/spokes/network.py
/usr/lib/python3.5/site-packages/astroid/bases.py:302: PyGIWarning: NM was imported without specifying a version first. Use gi.require_version('NM', '1.0') before import to ensure that the right version gets loaded.
  for res in _func(node, context, **kwargs):
************* Module ../pyanaconda/ui/gui/spokes/lib/accordion.py
/usr/lib/python3.5/site-packages/astroid/context.py:49: PyGIWarning: AnacondaWidgets was imported without specifying a version first. Use gi.require_version('AnacondaWidgets', '3.0') before import to ensure that the right version gets loaded.
  for result in generator:
************* Unused False Positives Found:
^E0611.*: No name '_isys' in module 'pyanaconda'$
PASS pylint/runpylint.py (exit status: 0)
